Workbook

Sheet Dashboard
B1: District 6 County Health Dashboard
B2: Data Source: Rural Health Innovation Center (2018-2022)
B3: Select County: | C3: Population | D3: Median Household Income | E3: Disbility (%) | F3: Current Smokers(%) | G3: Adults with BMI > 30.0 (Obese) (%) | H3: Life Expectancy (Years)
B4: Glascock | C4: =_xlfn.XLOOKUP(Dashboard!B4,'Cleaned Data'!A5:A17,'Cleaned Data'!B5:B17) -> 2903 | D4: =_xlfn.XLOOKUP(Dashboard!B4,'Cleaned Data'!A5:A17,'Cleaned Data'!CP5:CP17) -> 60469 | E4: =_xlfn.XLOOKUP(Dashboard!C4,'Cleaned Data'!B5:B17,'Cleaned Data'!O5:O17) -> 0.1614 | F4: =_xlfn.XLOOKUP(Dashboard!B4,'Cleaned Data'!A5:A17,'Cleaned Data'!Y5:Y17) -> 0.208 | G4: =_xlfn.XLOOKUP(Dashboard!B4,'Cleaned Data'!A5:A17,'Cleaned Data'!AT5:AT17) -> 0.177 | H4: =_xlfn.XLOOKUP(Dashboard!B4,'Cleaned Data'!A5:A17,'Cleaned Data'!AV5:AV17) -> 73.71
B12: Demographics | E12: Health Outcomes | H12: Health Behaviors
B13: Indicator | C13: Value | E13: Indicator | F13: Value | H13: Indicator | I13: Value
B14: Population Density | C14: =_xlfn.XLOOKUP(Dashboard!B4,'Cleaned Data'!A5:A17,'Cleaned Data'!D5:D17) -> 20 | E14: Crude Death Rate (per 100,000) | F14: =_xlfn.XLOOKUP(Dashboard!B4,'Cleaned Data'!A5:A17, 'Cleaned Data'!AY5:AY17) -> 135.1 | H14: Poor Mental Health Days (Month) | I14: =_xlfn.XLOOKUP(Dashboard!B4,'Cleaned Data'!A5:A17, 'Cleaned Data'!BA5:BA17) -> 5.7
B15: Male (%) | C15: =_xlfn.XLOOKUP(Dashboard!B4,'Cleaned Data'!A5:A17, 'Cleaned Data'!J5:J17) -> 0.4568 | E15: Total HIV/AIDS Rate (per 100,000) | F15: =_xlfn.XLOOKUP(Dashboard!B4,'Cleaned Data'!A5:A17,'Cleaned Data'!AL5:AL17) -> 0 | H15: Excessive Drinking (%) | I15: =_xlfn.XLOOKUP(Dashboard!B4,'Cleaned Data'!A5:A17,'Cleaned Data'!AA5:AA17) -> 0.1592
B16: Female (%) | C16: =_xlfn.XLOOKUP(Dashboard!B4,'Cleaned Data'!A5:A17, 'Cleaned Data'!K5:K17) -> 0.5432 | E16: Chlamydie Rate (per 100,000) | F16: =_xlfn.XLOOKUP(Dashboard!B4,'Cleaned Data'!A5:A17,'Cleaned Data'!AD5:AD17) -> 306.23 | H16: Teen Birth Rate (15-19yrs) | I16: =_xlfn.XLOOKUP(Dashboard!B4,'Cleaned Data'!A5:A17,'Cleaned Data'!U5:U17) -> 0
B17: Median Age | C17: =_xlfn.XLOOKUP(Dashboard!B4,'Cleaned Data'!A5:A17,'Cleaned Data'!L5:L17) -> 43.2 | E17: Gonorrhea Rate (per 100,000) | F17: =_xlfn.XLOOKUP(Dashboard!B4,'Cleaned Data'!A5:A17,'Cleaned Data'!AG5:AG17) -> 137 | H17: Youth (16–19) Not in School/Work (%) | I17: =_xlfn.XLOOKUP(Dashboard!B4,'Cleaned Data'!A5:A17,'Cleaned Data'!BH5:BH17) -> 0.027

Sheet County Comparisons
A2: Demographics
A38: Health Behaviors
A89: Health Outcomes
A124: Healthcare Workforce

Sheet County Snapshots
A1: County: | C1: Burke | F1: County: | H1: Columbia | K1: County: | M1: Emanuel | P1: County: | R1: Glascock | U1: County: | W1: Jefferson | Z1: County: | AB1: Jenkins | AE1: County: | AG1: Lincoln | AJ1: County: | AL1: McDuffie | AO1: County: | AQ1: Richmond | AT1: County: | AV1: Screven | AY1: County: | BA1: Taliferro | BD1: County: | BF1: Warren | BI1: County: | BK1: Wilkes | BN1: County: | BP1: Georgia | BS1: County: | BU1: United States
A2: Category | B2: Data Sources | F2: Category | G2: Data Sources | K2: Category | L2: Data Sources | P2: Category | Q2: Data Sources | U2: Category | V2: Data Sources | Z2: Category | AA2: Data Sources | AE2: Category | AF2: Data Sources | AJ2: Category | AK2: Data Sources | AO2: Category | AP2: Data Sources | AT2: Category | AU2: Data Sources | AY2: Category | AZ2: Data Sources | BD2: Category | BE2: Data Sources | BI2: Category | BJ2: Data Sources | BN2: Category | BO2: Data Sources | BS2: Category | BT2: Data Sources
A3: Demographics | B3: County Health Rankings | C3: Gerogia Rural Health Innovation Center (5yr Average) | E3: ` | F3: Demographics | G3: County Health Rankings | H3: Gerogia Rural Health Innovation Center (5yr Average) | K3: Demographics | L3: County Health Rankings | M3: Gerogia Rural Health Innovation Center (5yr Average) | P3: Demographics | Q3: County Health Rankings | R3: Gerogia Rural Health Innovation Center (5yr Average) | U3: Demographics | V3: County Health Rankings | W3: Gerogia Rural Health Innovation Center (5yr Average) | Z3: Demographics | AA3: County Health Rankings | AB3: Gerogia Rural Health Innovation Center (5yr Average) | AE3: Demographics | AF3: County Health Rankings | AG3: Gerogia Rural Health Innovation Center (5yr Average) | AJ3: Demographics | AK3: County Health Rankings | AL3: Gerogia Rural Health Innovation Center (5yr Average) | AO3: Demographics | AP3: County Health Rankings | AQ3: Gerogia Rural Health Innovation Center (5yr Average) | AT3: Demographics | AU3: County Health Rankings | AV3: Gerogia Rural Health Innovation Center (5yr Average) | AY3: Demographics | AZ3: County Health Rankings | BA3: Gerogia Rural Health Innovation Center (5yr Average) | BD3: Demographics | BE3: County Health Rankings | BF3: Gerogia Rural Health Innovation Center (5yr Average) | BI3: Demographics | BJ3: County Health Rankings | BK3: Gerogia Rural Health Innovation Center (5yr Average) | BN3: Demographics | BO3: County Health Rankings | BP3: Gerogia Rural Health Innovation Center (5yr Average) | BS3: Demographics | BT3: County Health Rankings | BU3: Gerogia Rural Health Innovation Center (5yr Average)
A4: Population | B4: 24388 | C4: ='Cleaned Data'!B5 -> 24337 | F4: Population | G4: 162419 | H4: ='Cleaned Data'!B6 -> 156921 | K4: Population | L4: 22929 | M4: ='Cleaned Data'!B7 -> 22907 | P4: Population | Q4: 2939 | R4: ='Cleaned Data'!B8 -> 2903 | U4: Population | V4: 15314 | W4: ='Cleaned Data'!B9 -> 15591 | Z4: Population | AA4: 8689 | AB4: ='Cleaned Data'!B10 -> 8704 | AE4: Population | AF4: 7841 | AG4: ='Cleaned Data'!B11 -> 7726 | AJ4: Population | AK4: 21713 | AL4: ='Cleaned Data'!B12 -> 21715 | AO4: Population | AP4: 206640 | AQ4: ='Cleaned Data'!B13 -> 206153 | AT4: Population | AU4: 13977 | AV4: ='Cleaned Data'!B14 -> 14026 | AY4: Population | AZ4: 1600 | BA4: ='Cleaned Data'!B15 -> 1635 | BD4: Population | BE4: 5155 | BF4: ='Cleaned Data'!B16 -> 5197 | BI4: Population | BJ4: 9599 | BK4: ='Cleaned Data'!B17 -> 9610 | BN4: Population | BO4: 10912876 | BP4: ='Cleaned Data'!B18 -> 10722325 | BS4: Population | BT4: - | BU4: 331097493
A5: % Male | B5: 0.479 | C5: ='Cleaned Data'!J5 -> 0.4908 | F5: % Male | G5: 0.49 | H5: ='Cleaned Data'!J6 -> 0.4903 | K5: % Male | L5: 0.506 | M5: ='Cleaned Data'!J7 -> 0.5073 | P5: % Male | Q5: 0.502 | R5: ='Cleaned Data'!J8 -> 0.4568 | U5: % Male | V5: 0.488 | W5: ='Cleaned Data'!J9 -> 0.4863 | Z5: % Male | AA5: 0.532 | AB5: ='Cleaned Data'!J10 -> 0.5006 | AE5: % Male | AF5: 0.48 | AG5: ='Cleaned Data'!J11 -> 0.4911 | AJ5: % Male | AK5: 0.472 | AL5: ='Cleaned Data'!J12 -> 0.4839 | AO5: % Male | AP5: 0.485 | AQ5: ='Cleaned Data'!J13 -> 0.4841 | AT5: % Male | AU5: 0.491 | AV5: ='Cleaned Data'!J14 -> 0.4807 | AY5: % Male | AZ5: 0.511 | BA5: ='Cleaned Data'!J15 -> 0.4489 | BD5: % Male | BE5: 0.478 | BF5: ='Cleaned Data'!J16 -> 0.4628 | BI5: % Male | BJ5: 0.475 | BK5: ='Cleaned Data'!J17 -> 0.5148 | BN5: % Male | BO5: 0.488 | BP5: ='Cleaned Data'!J18 -> 0.4891 | BS5: % Male | BT5: - | BU5: 0.5
A6: % Female | B6: 0.521 | C6: ='Cleaned Data'!K5 -> 0.5092 | F6: % Female | G6: 0.51 | H6: ='Cleaned Data'!K6 -> 0.5097 | K6: % Female | L6: 0.494 | M6: ='Cleaned Data'!K7 -> 0.4927 | P6: % Female | Q6: 0.498 | R6: ='Cleaned Data'!K8 -> 0.5432 | U6: % Female | V6: 0.512 | W6: ='Cleaned Data'!K9 -> 0.5137 | Z6: % Female | AA6: 0.468 | AB6: ='Cleaned Data'!K10 -> 0.4994 | AE6: % Female | AF6: 0.52 | AG6: ='Cleaned Data'!K11 -> 0.5089 | AJ6: % Female | AK6: 0.528 | AL6: ='Cleaned Data'!K12 -> 0.5161 | AO6: % Female | AP6: 0.515 | AQ6: ='Cleaned Data'!K13 -> 0.5159 | AT6: % Female | AU6: 0.509 | AV6: ='Cleaned Data'!K14 -> 0.5193 | AY6: % Female | AZ6: 0.489 | BA6: ='Cleaned Data'!K15 -> 0.5511 | BD6: % Female | BE6: 0.522 | BF6: ='Cleaned Data'!K16 -> 0.5372 | BI6: % Female | BJ6: 0.525 | BK6: ='Cleaned Data'!K17 -> 0.4852 | BN6: % Female | BO6: 0.512 | BP6: ='Cleaned Data'!K18 -> 0.5109 | BS6: % Female | BT6: - | BU6: 0.5
A7: % Living in Rural Area | B7: 0.752 | C7: - | F7: % Living in Rural Area | G7: 0.149 | H7: - | K7: % Living in Rural Area | L7: 0.682 | M7: - | P7: % Living in Rural Area | Q7: 1 | R7: - | U7: % Living in Rural Area | V7: 1 | W7: - | Z7: % Living in Rural Area | AA7: 1 | AB7: - | AE7: % Living in Rural Area | AF7: 1 | AG7: - | AJ7: % Living in Rural Area | AK7: 0.594 | AL7: - | AO7: % Living in Rural Area | AP7: 0.083 | AQ7: - | AT7: % Living in Rural Area | AU7: 1 | AV7: - | AY7: % Living in Rural Area | AZ7: 1 | BA7: - | BD7: % Living in Rural Area | BE7: 1 | BF7: - | BI7: % Living in Rural Area | BJ7: 1 | BK7: - | BN7: % Living in Rural Area | BO7: 0.259 | BP7: - | BS7: % Living in Rural Area | BT7: 0.2 | BU7: -
A8: White | B8: 11795 | C8: ='Cleaned Data'!CG5 -> 12127 | F8: White | G8: 104867 | H8: ='Cleaned Data'!CG6 -> 108715 | K8: White | L8: 13392 | M8: ='Cleaned Data'!CG7 -> 13861 | P8: White | Q8: 2555 | R8: ='Cleaned Data'!CG8 -> 2565 | U8: White | V8: 6481 | W8: ='Cleaned Data'!CG9 -> 6737 | Z8: White | AA8: 4342 | AB8: ='Cleaned Data'!CG10 -> 4985 | AE8: White | AF8: 5418 | AG8: ='Cleaned Data'!CG11 -> 5302 | AJ8: White | AK8: 11514 | AL8: ='Cleaned Data'!CG12 -> 11864 | AO8: White | AP8: 66521 | AQ8: ='Cleaned Data'!CG13 -> 71015 | AT8: White | AU8: 7758 | AV8: ='Cleaned Data'!CG14 -> 7938 | AY8: White | AZ8: 597 | BA8: ='Cleaned Data'!CG15 -> 599 | BD8: White | BE8: 2053 | BF8: ='Cleaned Data'!CG16 -> 1995 | BI8: White | BJ8: 4953 | BK8: ='Cleaned Data'!CG17 -> 5126 | BN8: White | BO8: 5500388 | BP8: ='Cleaned Data'!CG18 -> 5820019 | BS8: White | BT8: - | BU8: 218123424
A9: Black | B9: 11011 | C9: ='Cleaned Data'!CH5 -> 11095 | F9: Black | G9: 31936 | H9: ='Cleaned Data'!CH6 -> 26560 | K9: Black | L9: 7889 | M9: ='Cleaned Data'!CG8 -> 2565 | P9: Black | Q9: 248 | R9: 307 | U9: Black | V9: 7843 | W9: 8138 | Z9: Black | AA9: 3483 | AB9: 3036 | AE9: Black | AF9: 2035 | AG9: 2175 | AJ9: Black | AK9: 8772 | AL9: 8938 | AO9: Black | AP9: 119137 | AQ9: 115235 | AT9: Black | AU9: 5483 | AV9: 5629 | AY9: Black | AZ9: 829 | BA9: 822 | BD9: Black | BE9: 2862 | BF9: 3104 | BI9: Black | BJ9: 3721 | BK9: 3869 | BN9: Black | BO9: 3502283 | BP9: 3373948 | BS9: Black | BT9: - | BU9: 41288572
A10: Multiracial | B10: - | C10: ='Cleaned Data'!CM5 -> 670 | F10: Multiracial | G10: - | H10: 10399 | K10: Multiracial | L10: - | M10: 1220 | P10: Multiracial | Q10: - | R10: 29 | U10: Multiracial | V10: - | W10: 236 | Z10: Multiracial | AA10: - | AB10: 380 | AE10: Multiracial | AF10: - | AG10: 158 | AJ10: Multiracial | AK10: - | AL10: 605 | AO10: Multiracial | AP10: - | AQ10: 11937 | AT10: Multiracial | AU10: - | AV10: 352 | AY10: Multiracial | AZ10: - | BA10: 92 | BD10: Multiracial | BE10: - | BF10: 74 | BI10: Multiracial | BJ10: - | BK10: 323 | BN10: Multiracial | BO10: - | BP10: 638881 | BS10: Multiracial | BT10: - | BU10: 29142780
A11: Teen Birth Rate | B11: 28.5 | C11: ='Cleaned Data'!U5 -> 0 | F11: Teen Birth Rate | G11: 9.2 | H11: 2.41 | K11: Teen Birth Rate | L11: 37.8 | M11: 46.69 | P11: Teen Birth Rate | Q11: 33.7 | R11: 0 | U11: Teen Birth Rate | V11: 30.2 | W11: 20.13 | Z11: Teen Birth Rate | AA11: 30.8 | AB11: 0 | AE11: Teen Birth Rate | AF11: 13.9 | AG11: 0 | AJ11: Teen Birth Rate | AK11: 35.1 | AL11: 0 | AO11: Teen Birth Rate | AP11: 32 | AQ11: 27.9 | AT11: Teen Birth Rate | AU11: 43.8 | AV11: 0 | AY11: Teen Birth Rate | AZ11: 0 | BA11: 0 | BD11: Teen Birth Rate | BE11: 28.8 | BF11: 0 | BI11: Teen Birth Rate | BJ11: 26.6 | BK11: 0 | BN11: Teen Birth Rate | BO11: 19.6 | BP11: 12.67 | BS11: Teen Birth Rate | BT11: - | BU11: 9.63
A13: Health Behaviors | F13: Health Behaviors | K13: Health Behaviors | P13: Health Behaviors | U13: Health Behaviors | Z13: Health Behaviors | AE13: Health Behaviors | AJ13: Health Behaviors | AO13: Health Behaviors | AT13: Health Behaviors | AY13: Health Behaviors | BD13: Health Behaviors | BI13: Health Behaviors | BN13: Health Behaviors | BS13: Health Behaviors
A14: % Current Smokers | B14: 0.198 | C14: ='Cleaned Data'!Y5 -> 0.198 | F14: % Current Smokers | G14: 0.126 | H14: 0.198 | K14: % Current Smokers | L14: 0.236 | M14: 0.236 | P14: % Current Smokers | Q14: 0.208 | R14: 0.208 | U14: % Current Smokers | V14: 0.225 | W14: 0.225 | Z14: % Current Smokers | AA14: 0.256 | AB14: 0.256 | AE14: % Current Smokers | AF14: 0.214 | AG14: 0.214 | AJ14: % Current Smokers | AK14: 0.208 | AL14: 0.21 | AO14: % Current Smokers | AP14: 0.196 | AQ14: 0.196 | AT14: % Current Smokers | AU14: 0.199 | AV14: 0.1563 | AY14: % Current Smokers | AZ14: 0.222 | BA14: 0.222 | BD14: % Current Smokers | BE14: 0.238 | BF14: 0.238 | BI14: % Current Smokers | BJ14: 0.217 | BK14: 0.217 | BN14: % Current Smokers | BO14: 0.156 | BP14: 0.16 | BS14: % Current Smokers | BT14: 0.15 | BU14: 0.14
A15: % Adults w/ Excessive Drinking | B15: 0.143 | C15: ='Cleaned Data'!AA5 -> 0.1426 | F15: % Adults w/ Excessive Drinking | G15: 0.165 | H15: 0.1426 | K15: % Adults w/ Excessive Drinking | L15: 0.147 | M15: 0.1469 | P15: % Adults w/ Excessive Drinking | Q15: 0.159 | R15: 0.159 | U15: % Adults w/ Excessive Drinking | V15: 0.134 | W15: 0.1339 | Z15: % Adults w/ Excessive Drinking | AA15: 0.135 | AB15: 0.1353 | AE15: % Adults w/ Excessive Drinking | AF15: 0.137 | AG15: 0.1368 | AJ15: % Adults w/ Excessive Drinking | AK15: 0.139 | AL15: 0.14 | AO15: % Adults w/ Excessive Drinking | AP15: 0.156 | AQ15: 0.1563 | AT15: % Adults w/ Excessive Drinking | AU15: 0.145 | AV15: 0.1452 | AY15: % Adults w/ Excessive Drinking | AZ15: 0.117 | BA15: 0.1166 | BD15: % Adults w/ Excessive Drinking | BE15: 0.122 | BF15: 0.1216 | BI15: % Adults w/ Excessive Drinking | BJ15: 0.13 | BK15: 0.1299 | BN15: % Adults w/ Excessive Drinking | BO15: 0.166 | BP15: 0.17 | BS15: % Adults w/ Excessive Drinking | BT15: 0.18 | BU15: 0.18
A16: HIV/AIDS Prevalence | B16: 513 | C16: ='Cleaned Data'!AL5 -> <10 | F16: HIV/AIDS Prevalence | G16: 327 | H16: 7.4 | K16: HIV/AIDS Prevalence | L16: 327 | M16: >10 | P16: HIV/AIDS Prevalence | Q16: 279 | R16: >10 | U16: HIV/AIDS Prevalence | V16: 370 | W16: >10 | Z16: HIV/AIDS Prevalence | AA16: 391 | AB16: >10 | AE16: HIV/AIDS Prevalence | AF16: 298 | AG16: >10 | AJ16: HIV/AIDS Prevalence | AK16: 291 | AL16: >10 | AO16: HIV/AIDS Prevalence | AP16: 897 | AQ16: 40.4 | AT16: HIV/AIDS Prevalence | AU16: 323 | AV16: <10 | AY16: HIV/AIDS Prevalence | AZ16: 510 | BA16: 0 | BD16: HIV/AIDS Prevalence | BE16: 424 | BF16: 0 | BI16: HIV/AIDS Prevalence | BJ16: 331 | BK16: <10 | BN16: HIV/AIDS Prevalence | BO16: 657 | BP16: 27.4 | BS16: HIV/AIDS Prevalence | BT16: - | BU16: 13.3
A17: Chlamydia Incidence Rate | B17: 691.1 | C17: 692.96 | F17: Chlamydia Incidence Rate | G17: 317.6 | H17: 387.89 | K17: Chlamydia Incidence Rate | L17: 717.6 | M17: 937.68 | P17: Chlamydia Incidence Rate | Q17: 274.1 | R17: 306.23 | U17: Chlamydia Incidence Rate | V17: 657 | W17: 901.14 | Z17: Chlamydia Incidence Rate | AA17: 439.9 | AB17: 448.84 | AE17: Chlamydia Incidence Rate | AF17: 296.8 | AG17: 267.82 | AJ17: Chlamydia Incidence Rate | AK17: 799.7 | AL17: 907.29 | AO17: Chlamydia Incidence Rate | AP17: 1096.4 | AQ17: 1142.57 | AT17: Chlamydia Incidence Rate | AU17: 577.7 | AV17: 701.15 | AY17: Chlamydia Incidence Rate | AZ17: 577.7 | BA17: 625 | BD17: Chlamydia Incidence Rate | BE17: 763.4 | BF17: 969.93 | BI17: Chlamydia Incidence Rate | BJ17: 662.3 | BK17: 718.82 | BN17: Chlamydia Incidence Rate | BO17: 629.1 | BP17: 665.84 | BS17: Chlamydia Incidence Rate | BT17: - | BU17: 495
A18: % of Adults w/ Obesity | B18: 0.398 | C18: ='Cleaned Data'!AT5 -> 0.3 | F18: % of Adults w/ Obesity | G18: 0.344 | H18: 0.333 | K18: % of Adults w/ Obesity | L18: 0.413 | M18: 0.293 | P18: % of Adults w/ Obesity | Q18: 0.352 | R18: 0.177 | U18: % of Adults w/ Obesity | V18: 0.436 | W18: 0.244 | Z18: % of Adults w/ Obesity | AA18: 0.434 | AB18: 0.213 | AE18: % of Adults w/ Obesity | AF18: 0.386 | AG18: 0.195 | AJ18: % of Adults w/ Obesity | AK18: 0.394 | AL18: 0.27 | AO18: % of Adults w/ Obesity | AP18: 0.407 | AQ18: 0.381 | AT18: % of Adults w/ Obesity | AU18: 0.389 | AV18: 0.248 | AY18: % of Adults w/ Obesity | AZ18: 0.419 | BA18: 0.17 | BD18: % of Adults w/ Obesity | BE18: 0.431 | BF18: 0.205 | BI18: % of Adults w/ Obesity | BJ18: 0.418 | BK18: 0.193 | BN18: % of Adults w/ Obesity | BO18: 0.342 | BP18: 0.297 | BS18: % of Adults w/ Obesity | BT18: 0.34 | BU18: 0.3
A21: Health Outcomes | F21: Health Outcomes | K21: Health Outcomes | P21: Health Outcomes | U21: Health Outcomes | Z21: Health Outcomes | AE21: Health Outcomes | AJ21: Health Outcomes | AO21: Health Outcomes | AT21: Health Outcomes | AY21: Health Outcomes | BD21: Health Outcomes | BI21: Health Outcomes | BN21: Health Outcomes | BS21: Health Outcomes
A22: 5 Year Total Deaths: Heart Disease | B22: - | C22: ='Cleaned Data'!AX5 -> 126 | F22: 5 Year Total Deaths: Heart Disease | G22: - | H22: 396 | K22: 5 Year Total Deaths: Heart Disease | L22: - | M22: 152 | P22: 5 Year Total Deaths: Heart Disease | Q22: - | R22: 20 | U22: 5 Year Total Deaths: Heart Disease | V22: - | W22: 102 | Z22: 5 Year Total Deaths: Heart Disease | AA22: - | AB22: 31 | AE22: 5 Year Total Deaths: Heart Disease | AF22: - | AG22: 42 | AJ22: 5 Year Total Deaths: Heart Disease | AK22: - | AL22: 126 | AO22: 5 Year Total Deaths: Heart Disease | AP22: - | AQ22: 976 | AT22: 5 Year Total Deaths: Heart Disease | AU22: - | AV22: 85 | AY22: 5 Year Total Deaths: Heart Disease | AZ22: - | BA22: No data | BD22: 5 Year Total Deaths: Heart Disease | BE22: - | BF22: 45 | BI22: 5 Year Total Deaths: Heart Disease | BJ22: - | BK22: 54 | BN22: 5 Year Total Deaths: Heart Disease | BO22: - | BP22: 40886 | BS22: 5 Year Total Deaths: Heart Disease | BT22: - | BU22: 1856446
A23: Average Poor Mental Health Days/Month | B23: 5.2 | C23: ='Cleaned Data'!BA5 -> 5.2 | F23: Average Poor Mental Health Days/Month | G23: 4.8 | H23: 4.8 | K23: Average Poor Mental Health Days/Month | L23: 5.6 | M23: 5.6 | P23: Average Poor Mental Health Days/Month | Q23: 5.7 | R23: 5.7 | U23: Average Poor Mental Health Days/Month | V23: 5.7 | W23: 5.7 | Z23: Average Poor Mental Health Days/Month | AA23: 5.8 | AB23: 5.8 | AE23: Average Poor Mental Health Days/Month | AF23: 5.7 | AG23: 5.7 | AJ23: Average Poor Mental Health Days/Month | AK23: 5.5 | AL23: 5.5 | AO23: Average Poor Mental Health Days/Month | AP23: 5.6 | AQ23: 5.6 | AT23: Average Poor Mental Health Days/Month | AU23: 5.4 | AV23: 5.4 | AY23: Average Poor Mental Health Days/Month | AZ23: 5.5 | BA23: 5.5 | BD23: Average Poor Mental Health Days/Month | BE23: 5.8 | BF23: 5.8 | BI23: Average Poor Mental Health Days/Month | BJ23: 5.6 | BK23: 5.6 | BN23: Average Poor Mental Health Days/Month | BO23: 4.8 | BP23: 4.8 | BS23: Average Poor Mental Health Days/Month | BT23: 4.8 | BU23: 4.9
A24: Premature Age-Adjusted Mortality Rate | B24: 568.1 | C24: - | F24: Premature Age-Adjusted Mortality Rate | G24: 318.1 | H24: - | K24: Premature Age-Adjusted Mortality Rate | L24: 705.8 | M24: - | P24: Premature Age-Adjusted Mortality Rate | Q24: 606.6 | R24: - | U24: Premature Age-Adjusted Mortality Rate | V24: 739.9 | W24: - | Z24: Premature Age-Adjusted Mortality Rate | AA24: 633.1 | AB24: - | AE24: Premature Age-Adjusted Mortality Rate | AF24: 510.2 | AG24: - | AJ24: Premature Age-Adjusted Mortality Rate | AK24: 633.4 | AL24: - | AO24: Premature Age-Adjusted Mortality Rate | AP24: 632.4 | AQ24: - | AT24: Premature Age-Adjusted Mortality Rate | AU24: 643.4 | AV24: - | AY24: Premature Age-Adjusted Mortality Rate | AZ24: 616.4 | BA24: - | BD24: Premature Age-Adjusted Mortality Rate | BE24: 656.4 | BF24: - | BI24: Premature Age-Adjusted Mortality Rate | BJ24: 611 | BK24: - | BN24: Premature Age-Adjusted Mortality Rate | BO24: 441.8 | BP24: - | BS24: Premature Age-Adjusted Mortality Rate | BT24: - | BU24: -
A25: Infant Mortality Rate | B25: 14 | C25: 6.9 | F25: Infant Mortality Rate | G25: 4 | H25: 5.1 | K25: Infant Mortality Rate | L25: 0 | M25: 8 | P25: Infant Mortality Rate | Q25: 0 | R25: 0 | U25: Infant Mortality Rate | V25: 0 | W25: 8.7 | Z25: Infant Mortality Rate | AA25: 0 | AB25: <4 | AE25: Infant Mortality Rate | AF25: 0 | AG25: <4 | AJ25: Infant Mortality Rate | AK25: 11 | AL25: 8.8 | AO25: Infant Mortality Rate | AP25: 11 | AQ25: 10.1 | AT25: Infant Mortality Rate | AU25: 0 | AV25: 8.9 | AY25: Infant Mortality Rate | AZ25: 0 | BA25: 0 | BD25: Infant Mortality Rate | BE25: 0 | BF25: <4 | BI25: Infant Mortality Rate | BJ25: 0 | BK25: <4 | BN25: Infant Mortality Rate | BO25: 7 | BP25: 6.8 | BS25: Infant Mortality Rate
A26: % of Frequent Mental Distress | B26: 18 | C26: - | F26: % of Frequent Mental Distress | G26: 0.15 | H26: - | K26: % of Frequent Mental Distress | L26: 0.19 | M26: - | P26: % of Frequent Mental Distress | Q26: 0.19 | R26: - | U26: % of Frequent Mental Distress | V26: 0.19 | W26: - | Z26: % of Frequent Mental Distress | AA26: 0.2 | AB26: - | AE26: % of Frequent Mental Distress | AF26: 0.19 | AG26: - | AJ26: % of Frequent Mental Distress | AK26: 0.18 | AL26: - | AO26: % of Frequent Mental Distress | AP26: 0.18 | AQ26: - | AT26: % of Frequent Mental Distress | AU26: 0.18 | AV26: - | AY26: % of Frequent Mental Distress | AZ26: 0.18 | BA26: - | BD26: % of Frequent Mental Distress | BE26: 0.19 | BF26: - | BI26: % of Frequent Mental Distress | BJ26: 0.19 | BK26: - | BN26: % of Frequent Mental Distress | BO26: 0.15 | BP26: - | BS26: % of Frequent Mental Distress
A29: Other Socio-demographic factors | F29: Other Socio-demographic factors | K29: Other Socio-demographic factors | P29: Other Socio-demographic factors | U29: Other Socio-demographic factors | Z29: Other Socio-demographic factors | AE29: Other Socio-demographic factors | AJ29: Other Socio-demographic factors | AO29: Other Socio-demographic factors | AT29: Other Socio-demographic factors | AY29: Other Socio-demographic factors | BD29: Other Socio-demographic factors | BI29: Other Socio-demographic factors | BN29: Other Socio-demographic factors | BS29: Other Socio-demographic factors
A30: % of Children in Poverty | B30: 0.295 | C30: - | F30: % of Children in Poverty | G30: 0.084 | H30: - | K30: % of Children in Poverty | L30: 0.28 | M30: - | P30: % of Children in Poverty | Q30: 0.186 | R30: - | U30: % of Children in Poverty | V30: 0.338 | W30: - | Z30: % of Children in Poverty | AA30: 0.348 | AB30: - | AE30: % of Children in Poverty | AF30: 0.247 | AG30: - | AJ30: % of Children in Poverty | AK30: 0.262 | AL30: - | AO30: % of Children in Poverty | AP30: 0.264 | AQ30: - | AT30: % of Children in Poverty | AU30: 0.298 | AV30: - | AY30: % of Children in Poverty | AZ30: 0.307 | BA30: - | BD30: % of Children in Poverty | BE30: 0.375 | BF30: - | BI30: % of Children in Poverty | BJ30: 0.282 | BK30: - | BN30: % of Children in Poverty | BO30: 0.172 | BP30: - | BS30: % of Children in Poverty | BT30: 0.16 | BU30: -
A31: % of Children in Single Parent Households | B31: 0.366 | C31: - | F31: % of Children in Single Parent Households | G31: 0.224 | H31: - | K31: % of Children in Single Parent Households | L31: 0.289 | M31: - | P31: % of Children in Single Parent Households | Q31: 0.355 | R31: - | U31: % of Children in Single Parent Households | V31: 0.404 | W31: - | Z31: % of Children in Single Parent Households | AA31: 0.488 | AB31: - | AE31: % of Children in Single Parent Households | AF31: 0.276 | AG31: - | AJ31: % of Children in Single Parent Households | AK31: 0.519 | AL31: - | AO31: % of Children in Single Parent Households | AP31: 0.511 | AQ31: - | AT31: % of Children in Single Parent Households | AU31: 0.432 | AV31: - | AY31: % of Children in Single Parent Households | AZ31: 0.289 | BA31: - | BD31: % of Children in Single Parent Households | BE31: 0.502 | BF31: - | BI31: % of Children in Single Parent Households | BJ31: 0.355 | BK31: - | BN31: % of Children in Single Parent Households | BO31: 0.306 | BP31: - | BS31: % of Children in Single Parent Households | BT31: 0.25 | BU31: -
A32: % Population Earning Under $25,000 | B32: - | C32: ='Cleaned Data'!CX5 -> 0.278 | F32: % Population Earning Under $25,000 | G32: - | H32: 0.1045 | K32: % Population Earning Under $25,000 | L32: - | M32: 0.247 | P32: % Population Earning Under $25,000 | Q32: - | R32: 0.2262 | U32: % Population Earning Under $25,000 | V32: - | W32: 0.2836 | Z32: % Population Earning Under $25,000 | AA32: - | AB32: 0.4146 | AE32: % Population Earning Under $25,000 | AF32: - | AG32: 0.2315 | AJ32: % Population Earning Under $25,000 | AK32: - | AL32: 0.2105 | AO32: % Population Earning Under $25,000 | AP32: - | AQ32: 0.2562 | AT32: % Population Earning Under $25,000 | AU32: - | AV32: 0.2405 | AY32: % Population Earning Under $25,000 | AZ32: - | BA32: 0.1928 | BD32: % Population Earning Under $25,000 | BE32: - | BF32: 0.2463 | BI32: % Population Earning Under $25,000 | BJ32: - | BK32: 0.2582 | BN32: % Population Earning Under $25,000 | BO32: - | BP32: 0.2299 | BS32: % Population Earning Under $25,000 | BT32: - | BU32: 0.1478
A33: % Population Earning $25,000 - $49,999 | B33: - | C33: ='Cleaned Data'!CY5 -> 0.2171 | F33: % Population Earning $25,000 - $49,999 | G33: - | H33: 0.134 | K33: % Population Earning $25,000 - $49,999 | L33: - | M33: 0.2813 | P33: % Population Earning $25,000 - $49,999 | Q33: - | R33: 0.2186 | U33: % Population Earning $25,000 - $49,999 | V33: - | W33: 0.2439 | Z33: % Population Earning $25,000 - $49,999 | AA33: - | AB33: 0.2718 | AE33: % Population Earning $25,000 - $49,999 | AF33: - | AG33: 0.2627 | AJ33: % Population Earning $25,000 - $49,999 | AK33: - | AL33: 0.2407 | AO33: % Population Earning $25,000 - $49,999 | AP33: - | AQ33: 0.2397 | AT33: % Population Earning $25,000 - $49,999 | AU33: - | AV33: 0.2598 | AY33: % Population Earning $25,000 - $49,999 | AZ33: - | BA33: 0.3795 | BD33: % Population Earning $25,000 - $49,999 | BE33: - | BF33: 0.3285 | BI33: % Population Earning $25,000 - $49,999 | BJ33: - | BK33: 0.2106 | BN33: % Population Earning $25,000 - $49,999 | BO33: - | BP33: 0.2251 | BS33: % Population Earning $25,000 - $49,999 | BT33: - | BU33: 0.1805
A34: Median Household Income | B34: 49431 | C34: ='Cleaned Data'!CP5 -> 50321 | F34: Median Household Income | G34: 94224 | H34: 92571 | K34: Median Household Income | L34: 46459 | M34: 47905 | P34: Median Household Income | Q34: 55539 | R34: 60469 | U34: Median Household Income | V34: 44459 | W34: 46865 | Z34: Median Household Income | AA34: 41830 | AB34: 31463 | AE34: Median Household Income | AF34: 69776 | AG34: 50754 | AJ34: Median Household Income | AK34: 50593 | AL34: 54752 | AO34: Median Household Income | AP34: 50079 | AQ34: 50605 | AT34: Median Household Income | AU34: 52713 | AV34: 49941 | AY34: Median Household Income | AZ34: 42138 | BA34: 45881 | BD34: Median Household Income | BE34: 44367 | BF34: 45091 | BI34: Median Household Income | BJ34: 47377 | BK34: 51780 | BN34: Median Household Income | BO34: 72742 | BP34: 71355 | BS34: Median Household Income | BT34: - | BU34: 75149
A35: % Population Unemployed | B35: 0.052 | C35: - | F35: % Population Unemployed | G35: 0.028 | H35: - | K35: % Population Unemployed | L35: 0.041 | M35: - | P35: % Population Unemployed | Q35: 0.03 | R35: - | U35: % Population Unemployed | V35: 0.04 | W35: - | Z35: % Population Unemployed | AA35: 0.042 | AB35: - | AE35: % Population Unemployed | AF35: 0.035 | AG35: - | AJ35: % Population Unemployed | AK35: 0.042 | AL35: - | AO35: % Population Unemployed | AP35: 0.042 | AQ35: - | AT35: % Population Unemployed | AU35: 0.043 | AV35: - | AY35: % Population Unemployed | AZ35: 0.043 | BA35: - | BD35: % Population Unemployed | BE35: 0.038 | BF35: - | BI35: % Population Unemployed | BJ35: 0.041 | BK35: - | BN35: % Population Unemployed | BO35: 0.037 | BP35: - | BS35: % Population Unemployed | BT35: 0.037 | BU35: -

Sheet Cleaned Data
A1: Key: Data Source
A2: Rural Health Innovation Center: 2018-2022 | B2: HealthyPeople 2030 | C2: Oasis (2018-2023) | D2: CDC (2022): GA state | E2: **indicates average of the data fro those that had more than 1 data source | G2: Average of Rural Health Innovation Center and Oasis
B3: Demographics | W3: Health Behaviors | AU3: Health Outcomes | BB3: Healthcare Workforce | BF3: Other Social & Economic Factors | BI3: Breast | BL3: Cervical | BO3: Colon and Rectum | BR3: Lung | BU3: Prostate
A4: Location | B4: Total Population | C4: Total Population | D4: Population Density (per sq. mi.) | E4: Percent of State Pop. | F4: Male | G4: Male | H4: Female | I4: Female | J4: Male % | K4: Female % | L4: Median Age | M4: Total Population (for determined disability status | N4: Popualtion w/ Disability | O4: Popualtion w/ Disability (%) | P4: Females Ages 15 to 19 | Q4: Teen Pregnancies by Residence | R4: # of Births by Residence | S4: Births to Teens | T4: Pregnancy Rate | U4: Births per 1,000 Teens | V4: Birth Rate (per 100,000 pop.) | W4: Population Age 18+ | X4: Current Smokers | Y4: Current Smokers, Percent | Z4: Adults Reporting Excessive Drinking | AA4: Percentage of Adults Reporting Excessive Drinking | AB4: Total Population | AC4: Chlammydia Infections | AD4: Chlamydia Infections per 100,000 pop. | AE4: Total Population | AF4: Gonorrhea Infections | AG4: Gonorrhea Infections per 100,000 pop. | AH4: Population Age 13+ | AI4: STD Cases by Residence | AJ4: STD Rate Per 100,000 Pop. | AK4: Total HIV/AIDS Infections # | AL4: Total HIV/AIDS Infections Rate Per 100,000 Pop. | AM4: Total Births | AN4: Infant Deaths (<1 yr old) | AO4: Infant Mortality Rate (per 1,000 Live Births) | AP4: Infant Deaths (<1 yr old) | AQ4: Infant Mortality Rate (per 1,000 Live Births) | AR4: Population Age 20+ | AS4: Adults with BMI > 30.0 (Obese) | AT4: Adults with BMI > 30.0 (Obese), Percent | AU4: Total Population (2019) | AV4: Life Expectancy at Birth (2019) | AW4: Total Population, 2018-2022 Average | AX4: 5 Year Total Death, CHD | AY4: Crude Death Rate per 100,000 Pop. CHD | AZ4: Population Age 18+ | BA4: Average Poor Mental Health Days per Month | BB4: Population Estimate | BC4: # of Mental Health Providers | BD4: Mental Health Providers to Population (1/person) | BE4: Mental Health Care Provider Rate (per 100,000 Pop.) | BF4: Population Age 16-19 | BG4: Population Age 16-19 Not in School and Not Employed | BH4: Population Age 16-19 Not in School and Not Employed, Percent | BI4: Estimated Total Population (Female) | BJ4: New Cases (Annual Average) | BK4: Breast | BL4: Estimated Total Population (Female) | BM4: New Cases (Annual Average) | BN4: Cervical | BO4: Estimated Total Population | BP4: New Cases (Annual Average) | BQ4: Colon and Rectum | BR4: Estimated Total Population | BS4: New Cases (Annual Average) | BT4: Lung | BU4: Estimated Total Population (Male) | BV4: New Cases (Annual Average) | BW4: Prostate | BX4: Demographics by Age | BY4: Age 0-4 | BZ4: Age 5-17 | CA4: Age 18-24 | CB4: Age 25-34 | CC4: Age 35-44 | CD4: Age 45-54 | CE4: Age 55-64 | CF4: Age 65+ | CG4: White | CH4: Black | CI4: Asian | CJ4: American Indian / Alaska Native | CK4: Native Hawaiian / Pacific Islander | CL4: Some Other Race | CM4: Multiple Races | CN4: Total Households | CO4: Average Household Income | CP4: Median Household Income | CQ4: 1-Person Household | CR4: 2-Person Household | CS4: 3-Person Household | CT4: 4-Person Household | CU4: 5-Person Household | CV4: 6-Person Household | CW4: 7-Person Household | CX4: Under $25,000 | CY4: $25,000 - $49,999 | CZ4: $50,000 - $99,999 | DA4: $100,000 - $199,999 | DB4: $200,000+
A5: Burke | B5: 24337 | C5: 140590 | D5: 29 | E5: 0.2 | F5: 11944 | G5: 66992 | H5: 12393 | I5: 73598 | J5: 0.4908 | K5: 0.5092 | L5: 38.8 | M5: 24134 | N5: 3578 | O5: 0.1483 | P5: 846 | Q5: 173 | R5: 134 | S5: 0 | T5: 18.2 | U5: 0 | V5: 14.1 | W5: 18351 | X5: 3633 | Y5: 0.198 | Z5: 2617 | AA5: 0.1426 | AB5: 24388 | AC5: 169 | AD5: 692.96 | AE5: 24310 | AF5: 70 | AG5: 287.9 | AH5: 20218 | AI5: 1480 | AJ5: 1052.7 | AK5: >10 | AL5: <10 | AM5: 258 | AN5: No data | AO5: No data | AP5: 12 | AQ5: 6.9 | AR5: 17631 | AS5: 5307 | AT5: 0.3 | AU5: 22383 | AV5: 74.14 | AW5: 23230 | AX5: 126 | AY5: 108.5 | AZ5: 18351 | BA5: 5.2 | BB5: 24388 | BC5: 11 | BD5: 2217.1 | BE5: 45.1 | BF5: 1686 | BG5: 99 | BH5: 0.0587 | BI5: 14716 | BJ5: 21 | BK5: 142.7 | BL5: No data | BM5: Suppressed | BN5: Suppressed | BO5: 26397 | BP5: 17 | BQ5: 64.4 | BR5: 29447 | BS5: 24 | BT5: 81.5 | BU5: 13416 | BV5: 15 | BW5: 111.8 | BY5: 1484 | BZ5: 4607 | CA5: 2662 | CB5: 2191 | CC5: 3070 | CD5: 2947 | CE5: 3409 | CF5: 3967 | CG5: 12127 | CH5: 11095 | CI5: 122 | CJ5: 0 | CK5: 0 | CL5: 323 | CM5: 670 | CN5: 8913 | CO5: 77372 | CP5: 50321 | CQ5: 25335 | CR5: 49137 | CS5: 59615 | CT5: 113323 | CU5: 105848 | CV5: 69282 | CW5: 95369 | CX5: 0.278 | CY5: 0.2171 | CZ5: 0.2598 | DA5: 0.1999 | DB5: 0.0451
A6: Columbia | B6: 156921 | C6: 958602 | D6: 541 | E6: 1.5 | F6: 76942 | G6: 468642 | H6: 79979 | I6: 489960 | J6: 0.4903 | K6: 0.5097 | L6: 37.4 | M6: 153471 | N6: 20021 | O6: 0.1305 | P6: 4971 | Q6: 398 | R6: 268 | S6: 12 | T6: 5.9 | U6: 2.41 | V6: 4 | W6: 120343 | X6: 15524 | Y6: 0.129 | Z6: 19831 | AA6: 0.1648 | AB6: 162419 | AC6: 630 | AD6: 387.89 | AE6: 159639 | AF6: 179 | AG6: 112.1 | AH6: 134743 | AI6: 4117 | AJ6: 429.5 | AK6: 10 | AL6: 7.4 | AM6: 1701 | AN6: No data | AO6: No data | AP6: 55 | AQ6: 5.1 | AR6: 116039 | AS6: 38641 | AT6: 0.332 | AU6: 156714 | AV6: 80.46 | AW6: 158688 | AX6: 396 | AY6: 49.9 | AZ6: 120343 | BA6: 4.8 | BB6: 162419 | BC6: 215 | BD6: 755.4 | BE6: 132.4 | BF6: 8219 | BG6: 314 | BH6: 0.0382 | BI6: 90694 | BJ6: 115 | BK6: 126.8 | BL6: 74074 | BM6: 4 | BN6: 5.4 | BO6: 165384 | BP6: 43 | BQ6: 26 | BR6: 164609 | BS6: 80 | BT6: 48.6 | BU6: 84967 | BV6: 104 | BW6: 122.4 | BY6: 9500 | BZ6: 29755 | CA6: 12875 | CB6: 21030 | CC6: 22631 | CD6: 19907 | CE6: 18281 | CF6: 22942 | CG6: 108715 | CH6: 26560 | CI6: 6850 | CJ6: 375 | CK6: 5 | CL6: 4017 | CM6: 10399 | CN6: 50056 | CO6: 114331 | CP6: 92571 | CQ6: 47156 | CR6: 97339 | CS6: 105722 | CT6: 135548 | CU6: 117500 | CV6: 126131 | CW6: 114696 | CX6: 0.1045 | CY6: 0.134 | CZ6: 0.2976 | DA6: 0.3285 | DB6: 0.1355
A7: Emanuel | B7: 22907 | C7: 136529 | D7: 34 | E7: 0.2 | F7: 11621 | G7: 68044 | H7: 11286 | I7: 68485 | J7: 0.5073 | K7: 0.4927 | L7: 37.4 | M7: 22045 | N7: 4687 | O7: 0.2126 | P7: 664 | Q7: 203 | R7: 167 | S7: 31 | T7: 21.5 | U7: 46.69 | V7: 17.7 | W7: 17112 | X7: 4038 | Y7: 0.236 | Z7: 2514 | AA7: 0.1469 | AB7: 22929 | AC7: 215 | AD7: 937.68 | AE7: 22716 | AF7: 72 | AG7: 317 | AH7: 18974 | AI7: 2544 | AJ7: 1130.9 | AK7: >10 | AL7: <10 | AM7: 277 | AN7: No data | AO7: No data | AP7: 14 | AQ7: 8 | AR7: 16352 | AS7: 4791 | AT7: 0.293 | AU7: 22646 | AV7: 73 | AW7: 22682 | AX7: 152 | AY7: 134 | AZ7: 17112 | BA7: 5.6 | BB7: 22929 | BC7: 23 | BD7: 996.9 | BE7: 100.3 | BF7: 1151 | BG7: 113 | BH7: 0.0982 | BI7: 15340 | BJ7: 16 | BK7: 104.3 | BL7: No data | BM7: Suppressed | BN7: Suppressed | BO7: 27173 | BP7: 15 | BQ7: 55.2 | BR7: 28822 | BS7: 23 | BT7: 79.8 | BU7: 13266 | BV7: 16 | BW7: 120.6 | BY7: 1585 | BZ7: 4132 | CA7: 1917 | CB7: 3249 | CC7: 2881 | CD7: 2571 | CE7: 2907 | CF7: 3665 | CG7: 13861 | CH7: 7345 | CI7: 47 | CJ7: 84 | CK7: 0 | CL7: 350 | CM7: 1220 | CN7: 8321 | CO7: 62820 | CP7: 47905 | CQ7: 25012 | CR7: 51113 | CS7: 53969 | CT7: 59097 | CU7: 77353 | CV7: 61429 | CW7: 82188 | CX7: 0.247 | CY7: 0.2813 | CZ7: 0.3069 | DA7: 0.1423 | DB7: 0.0225
A8: Glascock | B8: 2903 | C8: 17762 | D8: 20 | E8: 0 | F8: 1326 | G8: 8815 | H8: 1577 | I8: 8947 | J8: 0.4568 | K8: 0.5432 | L8: 43.2 | M8: 2819 | N8: 455 | O8: 0.1614 | P8: 176 | Q8: 17 | R8: 13 | S8: 0 | T8: 17.1 | U8: 0 | V8: 13.1 | W8: 2301 | X8: 479 | Y8: 0.208 | Z8: 366 | AA8: 0.1592 | AB8: 2939 | AC8: 9 | AD8: 306.23 | AE8: 2919 | AF8: 4 | AG8: 137 | AH8: 2524 | AI8: 54 | AJ8: 304 | AK8: 0 | AL8: 0 | AM8: 27 | AN8: No data | AO8: No data | AP8: 0 | AQ8: 0 | AR8: 2235 | AS8: 400 | AT8: 0.177 | AU8: 2971 | AV8: 73.71 | AW8: 2962 | AX8: 20 | AY8: 135.1 | AZ8: 2301 | BA8: 5.7 | BB8: 0 | BC8: 0 | BD8: No data | BE8: No data | BF8: 185 | BG8: 5 | BH8: 0.027 | BI8: No data | BJ8: Suppressed | BK8: Suppressed | BL8: No data | BM8: Suppressed | BN8: Suppressed | BO8: No data | BP8: Suppressed | BQ8: Suppressed | BR8: 3636 | BS8: 3 | BT8: 82.5 | BU8: No data | BV8: Suppressed | BW8: Suppressed | BY8: 141 | BZ8: 481 | CA8: 294 | CB8: 262 | CC8: 392 | CD8: 424 | CE8: 416 | CF8: 493 | CG8: 2565 | CH8: 307 | CI8: 0 | CJ8: 0 | CK8: 2 | CL8: 0 | CM8: 29 | CN8: 1052 | CO8: 74995 | CP8: 60469 | CQ8: 22679 | CR8: 72564 | CS8: 94167 | CT8: No data | CU8: 195303 | CV8: No data | CW8: 66875 | CX8: 0.2262 | CY8: 0.2186 | CZ8: 0.3165 | DA8: 0.1901 | DB8: 0.0485
A9: Jefferson | B9: 15591 | C9: 92080 | D9: 30 | E9: 0.1 | F9: 7582 | G9: 44715 | H9: 8009 | I9: 47365 | J9: 0.4863 | K9: 0.5137 | L9: 40.7 | M9: 15139 | N9: 2317 | O9: 0.153 | P9: 596 | Q9: 130 | R9: 78 | S9: 12 | T9: 22.6 | U9: 20.13 | V9: 13.5 | W9: 11965 | X9: 2692 | Y9: 0.225 | Z9: 1602 | AA9: 0.1339 | AB9: 15314 | AC9: 138 | AD9: 901.14 | AE9: 15524 | AF9: 38 | AG9: 244.8 | AH9: 12859 | AI9: 974 | AJ9: 1057.8 | AK9: >10 | AL9: <10 | AM9: 176 | AN9: No data | AO9: No data | AP9: 9 | AQ9: 8.7 | AR9: 11572 | AS9: 2812 | AT9: 0.244 | AU9: 15362 | AV9: 72.8 | AW9: 15379 | AX9: 102 | AY9: 132.6 | AZ9: 11965 | BA9: 5.7 | BB9: 15314 | BC9: 1 | BD9: 15314 | BE9: 6.5 | BF9: 977 | BG9: 39 | BH9: 0.0399 | BI9: 10869 | BJ9: 12 | BK9: 110.4 | BL9: No data | BM9: Suppressed | BN9: Suppressed | BO9: 21052 | BP9: 8 | BQ9: 38 | BR9: 21352 | BS9: 18 | BT9: 84.3 | BU9: 9685 | BV9: 16 | BW9: 165.2 | BY9: 921 | BZ9: 2709 | CA9: 1411 | CB9: 1778 | CC9: 1987 | CD9: 1786 | CE9: 2123 | CF9: 2876 | CG9: 6737 | CH9: 8138 | CI9: 68 | CJ9: 9 | CK9: 0 | CL9: 403 | CM9: 236 | CN9: 5826 | CO9: 64495 | CP9: 46865 | CQ9: 24311 | CR9: 53385 | CS9: 73668 | CT9: 57794 | CU9: 53901 | CV9: 107794 | CW9: 81750 | CX9: 0.2836 | CY9: 0.2439 | CZ9: 0.2592 | DA9: 0.1924 | DB9: 0.0209
A10: Jenkins | B10: 8704 | C10: 52060 | D10: 25 | E10: 0.1 | F10: 4357 | G10: 27749 | H10: 4347 | I10: 24311 | J10: 0.5006 | K10: 0.4994 | L10: 44 | M10: 7919 | N10: 1738 | O10: 0.2195 | P10: 305 | Q10: 48 | R10: 44 | S10: 0 | T10: 17.1 | U10: 0 | V10: 15.7 | W10: 6935 | X10: 1775 | Y10: 0.256 | Z10: 938 | AA10: 0.1353 | AB10: 8689 | AC10: 39 | AD10: 448.84 | AE10: 8639 | AF10: 16 | AG10: 185.2 | AH10: 7487 | AI10: 322 | AJ10: 618.5 | AK10: >10 | AL10: <10 | AM10: 90 | AN10: No data | AO10: No data | AP10: 3 | AQ10: <4 | AR10: 6726 | AS10: 1426 | AT10: 0.213 | AU10: 8676 | AV10: 73.61 | AW10: 8687 | AX10: 31 | AY10: 71.4 | AZ10: 6935 | BA10: 5.8 | BB10: 8689 | BC10: 1 | BD10: 8689 | BE10: 11.5 | BF10: 440 | BG10: 35 | BH10: 0.0795 | BI10: 5993 | BJ10: 7 | BK10: 116.8 | BL10: No data | BM10: Suppressed | BN10: Suppressed | BO10: No data | BP10: Suppressed | BQ10: Suppressed | BR10: 12145 | BS10: 6 | BT10: 49.4 | BU10: 5405 | BV10: 4 | BW10: 74 | BY10: 266 | BZ10: 1357 | CA10: 474 | CB10: 910 | CC10: 1379 | CD10: 915 | CE10: 1552 | CF10: 1851 | CG10: 4985 | CH10: 3036 | CI10: 2 | CJ10: 2 | CK10: 0 | CL10: 299 | CM10: 380 | CN10: 3297 | CO10: 48434 | CP10: 31463 | CQ10: 23161 | CR10: 31690 | CS10: 62264 | CT10: 40039 | CU10: 49979 | CV10: No data | CW10: No data | CX10: 0.4146 | CY10: 0.2718 | CZ10: 0.1783 | DA10: 0.1332 | DB10: 0.0021
A11: Lincoln | B11: 7726 | C11: 47336 | D11: 37 | E11: 0.1 | F11: 3794 | G11: 22946 | H11: 3932 | I11: 24390 | J11: 0.4911 | K11: 0.5089 | L11: 47.1 | M11: 7639 | N11: 1434 | O11: 0.1877 | P11: 291 | Q11: 21 | R11: 16 | S11: 0 | T11: 8.5 | U11: 0 | V11: 6.5 | W11: 6276 | X11: 1343 | Y11: 0.214 | Z11: 858 | AA11: 0.1368 | AB11: 7841 | AC11: 21 | AD11: 267.82 | AE11: 7749 | AF11: 15 | AG11: 193.6 | AH11: 6797 | AI11: 209 | AJ11: 441.5 | AK11: >10 | AL11: <10 | AM11: 78 | AN11: No data | AO11: No data | AP11: 2 | AQ11: <4 | AR11: 6154 | AS11: 1200 | AT11: 0.195 | AU11: 7921 | AV11: 76.67 | AW11: 7891 | AX11: 42 | AY11: 106.4 | AZ11: 6276 | BA11: 5.7 | BB11: 7841 | BC11: 3 | BD11: 2613.7 | BE11: 38.3 | BF11: 413 | BG11: 16 | BH11: 0.0387 | BI11: 6482 | BJ11: 8 | BK11: 123.4 | BL11: No data | BM11: Suppressed | BN11: Suppressed | BO11: 13452 | BP11: 6 | BQ11: 44.6 | BR11: 12784 | BS11: 9 | BT11: 70.4 | BU11: 7568 | BV11: 8 | BW11: 105.7 | BY11: 315 | BZ11: 1176 | CA11: 540 | CB11: 654 | CC11: 953 | CD11: 910 | CE11: 1265 | CF11: 1913 | CG11: 5302 | CH11: 2175 | CI11: 6 | CJ11: 0 | CK11: 0 | CL11: 85 | CM11: 158 | CN11: 3015 | CO11: 71037 | CP11: 50754 | CQ11: 17546 | CR11: 54880 | CS11: 46447 | CT11: 101060 | CU11: 170192 | CV11: No data | CW11: No data | CX11: 0.2315 | CY11: 0.2627 | CZ11: 0.2342 | DA11: 0.2338 | DB11: 0.0378
A12: McDuffie | B12: 21715 | C12: 129150 | D12: 84 | E12: 0.2 | F12: 10508 | G12: 60679 | H12: 11207 | I12: 68471 | J12: 0.4839 | K12: 0.5161 | L12: 38.5 | M12: 21469 | N12: 2634 | O12: 0.1227 | P12: 526 | Q12: 194 | R12: 147 | S12: 0 | T12: 21.5 | U12: 0 | V12: 16.3 | W12: 16278 | X12: 3386 | Y12: 0.208 | Z12: 2258 | AA12: 0.1388 | AB12: 21713 | AC12: 197 | AD12: 907.29 | AE12: 21633 | AF12: 111 | AG12: 513.1 | AH12: 17975 | AI12: 1491 | AJ12: 1154.5 | AK12: >10 | AL12: <10 | AM12: 266 | AN12: No data | AO12: No data | AP12: 14 | AQ12: 8.8 | AR12: 15760 | AS12: 4271 | AT12: 0.271 | AU12: 21312 | AV12: 74.17 | AW12: 21470 | AX12: 126 | AY12: 117.4 | AZ12: 16278 | BA12: 5.5 | BB12: 21713 | BC12: 15 | BD12: 1447.5 | BE12: 69.1 | BF12: 1028 | BG12: 116 | BH12: 0.1128 | BI12: 13494 | BJ12: 19 | BK12: 140.8 | BL12: No data | BM12: Suppressed | BN12: Suppressed | BO12: 28192 | BP12: 17 | BQ12: 60.3 | BR12: 30349 | BS12: 20 | BT12: 65.9 | BU12: 13706 | BV12: 25 | BW12: 182.4 | BY12: 1358 | BZ12: 4044 | CA12: 1608 | CB12: 2770 | CC12: 2500 | CD12: 2534 | CE12: 3008 | CF12: 3893 | CG12: 11864 | CH12: 8938 | CI12: 34 | CJ12: 0 | CK12: 0 | CL12: 274 | CM12: 605 | CN12: 8212 | CO12: 72508 | CP12: 54752 | CQ12: 29357 | CR12: 57083 | CS12: 58690 | CT12: 71274 | CU12: No data | CV12: No data | CW12: No data | CX12: 0.2105 | CY12: 0.2407 | CZ12: 0.3162 | DA12: 0.2019 | DB12: 0.0306
A13: Richmond | B13: 206153 | C13: 1223878 | D13: 636 | E13: 1.9 | F13: 99791 | G13: 593236 | H13: 106362 | I13: 630642 | J13: 0.4841 | K13: 0.5159 | L13: 34.8 | M13: 194852 | N13: 35690 | O13: 0.1832 | P13: 6738 | Q13: 1681 | R13: 1146 | S13: 188 | T13: 22.3 | U13: 27.9 | V13: 15.2 | W13: 159044 | X13: 31173 | Y13: 0.196 | Z13: 24865 | AA13: 0.1563 | AB13: 206640 | AC13: 2361 | AD13: 1142.57 | AE13: 205673 | AF13: 1099 | AG13: 534.3 | AH13: 173064 | AI13: 22104 | AJ13: 1806.1 | AK13: 70 | AL13: 40.4 | AM13: 2871 | AN13: 29 | AO13: 10.2 | AP13: 164 | AQ13: 10.1 | AR13: 152129 | AS13: 57809 | AT13: 0.381 | AU13: 202518 | AV13: 74.18 | AW13: 203693 | AX13: 976 | AY13: 95.8 | AZ13: 159044 | BA13: 5.6 | BB13: 206640 | BC13: 719 | BD13: 287.4 | BE13: 347.9 | BF13: 11592 | BG13: 1226 | BH13: 0.1058 | BI13: 122131 | BJ13: 165 | BK13: 135.1 | BL13: 95652 | BM13: 11 | BN13: 11.5 | BO13: 216666 | BP13: 78 | BQ13: 36 | BR13: 228985 | BS13: 158 | BT13: 69 | BU13: 107355 | BV13: 162 | BW13: 150.9 | BY13: 13503 | BZ13: 33728 | CA13: 23345 | CB13: 32995 | CC13: 24866 | CD13: 22088 | CE13: 25637 | CF13: 29991 | CG13: 71015 | CH13: 115235 | CI13: 3659 | CJ13: 252 | CK13: 148 | CL13: 3907 | CM13: 11937 | CN13: 74028 | CO13: 70310 | CP13: 50605 | CQ13: 31083 | CR13: 60608 | CS13: 65208 | CT13: 74934 | CU13: 63995 | CV13: 82438 | CW13: 68942 | CX13: 0.2562 | CY13: 0.2397 | CZ13: 0.3005 | DA13: 0.1585 | DB13: 0.0452
A14: Screven | B14: 14026 | C14: 84172 | D14: 22 | E14: 0.1 | F14: 6742 | G14: 41512 | H14: 7284 | I14: 42660 | J14: 0.4807 | K14: 0.5193 | L14: 41.9 | M14: 13674 | N14: 2109 | O14: 0.1542 | P14: 393 | Q14: 107 | R14: 85 | S14: 0 | T14: 25.3 | U14: 0 | V14: 20.1 | W14: 11274 | X14: 2244 | Y14: 0.199 | Z14: 1637 | AA14: 0.1452 | AB14: 13977 | AC14: 98 | AD14: 701.15 | AE14: 14105 | AF14: 39 | AG14: 276.5 | AH14: 11972 | AI14: 740 | AJ14: 879.2 | AK14: >10 | AL14: <10 | AM14: 167 | AN14: No data | AO14: No data | AP14: 9 | AQ14: 8.9 | AR14: 10899 | AS14: 2703 | AT14: 0.248 | AU14: 13966 | AV14: 74.94 | AW14: 14000 | AX14: 85 | AY14: 121.4 | AZ14: 11274 | BA14: 5.4 | BB14: 13977 | BC14: 5 | BD14: 2795.4 | BE14: 35.8 | BF14: 525 | BG14: 127 | BH14: 0.2419 | BI14: 10560 | BJ14: 13 | BK14: 123.1 | BL14: No data | BM14: Suppressed | BN14: Suppressed | BO14: 21231 | BP14: 10 | BQ14: 47.1 | BR14: 21604 | BS14: 14 | BT14: 64.8 | BU14: 10840 | BV14: 12 | BW14: 110.7 | BY14: 763 | BZ14: 2123 | CA14: 890 | CB14: 1766 | CC14: 1845 | CD14: 1687 | CE14: 2168 | CF14: 2784 | CG14: 7938 | CH14: 5629 | CI14: 56 | CJ14: 12 | CK14: 0 | CL14: 39 | CM14: 352 | CN14: 4727 | CO14: 73243 | CP14: 49941 | CQ14: 23094 | CR14: 59286 | CS14: 72697 | CT14: 115568 | CU14: 39129 | CV14: 96731 | CW14: 63125 | CX14: 0.2405 | CY14: 0.2598 | CZ14: 0.2634 | DA14: 0.1963 | DB14: 0.04
A15: Taliaferro | B15: 1635 | C15: 9474 | D15: 8 | E15: 0 | F15: 734 | G15: 4746 | H15: 901 | I15: 4728 | J15: 0.4489 | K15: 0.5511 | L15: 47.2 | M15: 1630 | N15: 369 | O15: 0.2264 | P15: 7 | Q15: 5 | R15: 4 | S15: 0 | T15: 12.3 | U15: 0 | V15: >4 | W15: 1271 | X15: 282 | Y15: 0.222 | Z15: 148 | AA15: 0.1166 | AB15: 1600 | AC15: 10 | AD15: 625 | AE15: 1558 | AF15: 3 | AG15: 192.6 | AH15: 1392 | AI15: 69 | AJ15: 728.3 | AK15: 0 | AL15: 0 | AM15: 14 | AN15: No data | AO15: No data | AP15: 0 | AQ15: 0 | AR15: 1280 | AS15: 215 | AT15: 0.17 | AU15: 1537 | AV15: 74.8 | AW15: 1573 | AX15: No data | AY15: No data | AZ15: 1271 | BA15: 5.5 | BB15: 0 | BC15: 0 | BD15: No data | BE15: No data | BF15: 24 | BG15: 0 | BH15: 0 | BI15: No data | BJ15: Suppressed | BK15: Suppressed | BL15: No data | BM15: Suppressed | BN15: Suppressed | BO15: No data | BP15: Suppressed | BQ15: Suppressed | BR15: No data | BS15: Suppressed | BT15: Suppressed | BU15: No data | BV15: Suppressed | BW15: Suppressed | BY15: 67 | BZ15: 172 | CA15: 96 | CB15: 243 | CC15: 206 | CD15: 208 | CE15: 186 | CF15: 457 | CG15: 599 | CH15: 822 | CI15: 1 | CJ15: 0 | CK15: 4 | CL15: 117 | CM15: 92 | CN15: 643 | CO15: 54144 | CP15: 45881 | CQ15: 41053 | CR15: 32639 | CS15: 68750 | CT15: 64224 | CU15: No data | CV15: No data | CW15: No data | CX15: 0.1928 | CY15: 0.3795 | CZ15: 0.3173 | DA15: 0.0995 | DB15: 0.0109
A16: Warren | B16: 5197 | C16: 31238 | D16: 18 | E16: 0 | F16: 2405 | G16: 14789 | H16: 2792 | I16: 16449 | J16: 0.4628 | K16: 0.5372 | L16: 45.3 | M16: 5122 | N16: 932 | O16: 0.182 | P16: 178 | Q16: 40 | R16: 28 | S16: 0 | T16: 21.8 | U16: 0 | V16: 15.3 | W16: 4180 | X16: 995 | Y16: 0.238 | Z16: 508 | AA16: 0.1216 | AB16: 5155 | AC16: 50 | AD16: 969.93 | AE16: 5240 | AF16: 20 | AG16: 381.7 | AH16: 4422 | AI16: 347 | AJ16: 1110.8 | AK16: 0 | AL16: 0 | AM16: 55 | AN16: No data | AO16: No data | AP16: 3 | AQ16: <4 | AR16: 4054 | AS16: 827 | AT16: 0.205 | AU16: 5254 | AV16: 74.83 | AW16: 5226 | AX16: 45 | AY16: 172.2 | AZ16: 4180 | BA16: 5.8 | BB16: 5155 | BC16: 2 | BD16: 2577.5 | BE16: 38.8 | BF16: 211 | BG16: 7 | BH16: 0.0332 | BI16: 4345 | BJ16: 8 | BK16: 184.1 | BL16: No data | BM16: Suppressed | BN16: Suppressed | BO16: 7278 | BP16: 5 | BQ16: 68.7 | BR16: 8918 | BS16: 8 | BT16: 89.7 | BU16: 3906 | BV16: 4 | BW16: 102.4 | BY16: 277 | BZ16: 780 | CA16: 448 | CB16: 502 | CC16: 579 | CD16: 619 | CE16: 814 | CF16: 1178 | CG16: 1995 | CH16: 3104 | CI16: 24 | CJ16: 0 | CK16: 0 | CL16: 0 | CM16: 74 | CN16: 1945 | CO16: 57899 | CP16: 45091 | CQ16: 32630 | CR16: 41948 | CS16: 53264 | CT16: 84821 | CU16: 63958 | CV16: No data | CW16: 29000 | CX16: 0.2463 | CY16: 0.3285 | CZ16: 0.2746 | DA16: 0.1296 | DB16: 0.0211
A17: Wilkes | B17: 9610 | C17: 57977 | D17: 20 | E17: 0.1 | F17: 4947 | G17: 27889 | H17: 4663 | I17: 30088 | J17: 0.5148 | K17: 0.4852 | L17: 45.5 | M17: 9510 | N17: 1465 | O17: 0.154 | P17: 147 | Q17: 63 | R17: 44 | S17: 0 | T17: 18.1 | U17: 0 | V17: 12.6 | W17: 7547 | X17: 1638 | Y17: 0.217 | Z17: 980 | AA17: 0.1299 | AB17: 9599 | AC17: 69 | AD17: 718.82 | AE17: 9513 | AF17: 45 | AG17: 473 | AH17: 8225 | AI17: 530 | AJ17: 914.2 | AK17: >10 | AL17: <10 | AM17: 94 | AN17: No data | AO17: No data | AP17: 3 | AQ17: <4 | AR17: 7342 | AS17: 1417 | AT17: 0.193 | AU17: 9777 | AV17: 74.86 | AW17: 9692 | AX17: 54 | AY17: 111.4 | AZ17: 7547 | BA17: 5.6 | BB17: 9599 | BC17: 2 | BD17: 4799.5 | BE17: 20.8 | BF17: 360 | BG17: 14 | BH17: 0.0389 | BI17: 8431 | BJ17: 10 | BK17: 118.6 | BL17: No data | BM17: Suppressed | BN17: Suppressed | BO17: 17331 | BP17: 10 | BQ17: 57.7 | BR17: 16920 | BS17: 10 | BT17: 59.1 | BU17: 7751 | BV17: 8 | BW17: 103.2 | BY17: 521 | BZ17: 1462 | CA17: 612 | CB17: 1153 | CC17: 1001 | CD17: 1145 | CE17: 1470 | CF17: 2246 | CG17: 5126 | CH17: 3869 | CI17: 0 | CJ17: 16 | CK17: 0 | CL17: 276 | CM17: 323 | CN17: 4032 | CO17: 67375 | CP17: 51780 | CQ17: 24757 | CR17: 61413 | CS17: 62857 | CT17: 86289 | CU17: 80184 | CV17: No data | CW17: No data | CX17: 0.2582 | CY17: 0.2106 | CZ17: 0.3366 | DA17: 0.1746 | DB17: 0.0201
A18: Georgia (State) | B18: 10722325 | C18: 64588584 | D18: 186 | E18: 100 | F18: 5244476 | G18: 31452814 | H18: 5477849 | I18: 33135770 | J18: 0.4891 | K18: 0.5109 | L18: 37.2 | M18: 10531900 | N18: 1336645 | O18: 0.1269 | P18: 372109 | Q18: 56188 | R18: 39978 | S18: 4714 | T18: 12.9 | U18: 12.67 | V18: 9.2 | W18: 8315530 | X18: 1297223 | Y18: 0.156 | Z18: 1380818 | AA18: 0.1661 | AB18: 10912876 | AC18: 72662 | AD18: 665.84 | AE18: 10912876 | AF18: 31450 | AG18: 288.2 | AH18: 9170559 | AI18: 603324 | AJ18: 934.1 | AK18: 2511 | AL18: 27.4 | AM18: 124310 | AN18: 534 | AO18: 4.3 | AP18: 5109 | AQ18: 6.8 | AR18: 7979399 | AS18: 2382343 | AT18: 0.297 | AU18: 10617423 | AV18: 78.01 | AW18: 10711871 | AX18: 40886 | AY18: 76.3 | AZ18: 16631473 | BA18: 4.9 | BB18: 10912880 | BC18: 19531 | BD18: 558.7 | BE18: 179 | BF18: 602479 | BG18: 47447 | BH18: 0.0788 | BI18: 6241486 | BJ18: 8064 | BK18: 129.2 | BL18: 5487500 | BM18: 439 | BN18: 8 | BO18: 11567430 | BP18: 4546 | BQ18: 39.3 | BR18: 11891191 | BS18: 6885 | BT18: 57.9 | BU18: 5724573 | BV18: 7711 | BW18: 134.7 | BY18: 635299 | BZ18: 1877246 | CA18: 1051160 | CB18: 1475136 | CC18: 1420198 | CD18: 1401400 | CE18: 1321441 | CF18: 1540445 | CG18: 5820019 | CH18: 3373948 | CI18: 465487 | CJ18: 37920 | CK18: 7411 | CL18: 378659 | CM18: 638881 | CN18: 3946490 | CO18: 99345 | CP18: 71355 | CQ18: 38351 | CR18: 78456 | CS18: 89398 | CT18: 105220 | CU18: 95131 | CV18: 93261 | CW18: 105104 | CX18: 0.2299 | CY18: 0.2251 | CZ18: 0.2993 | DA18: 0.1977 | DB18: 0.048
A19: United States (as a whole) | B19: 331097593 | D19: 94 | F19: 164200298 | H19: 166897295 | J19: 0.4959 | K19: 0.5041 | L19: 38.5 | M19: 326147510 | N19: 41941456 | O19: 0.1286 | P19: 10683985 | S19: 102904 | U19: 9.63 | W19: 259755978 | X19: 36442044 | Y19: 0.14 | Z19: 47041079 | AA19: 0.1811 | AB19: 333287557 | AC19: 1649716 | AD19: 495 | AE19: 333287557 | AF19: 648056 | AG19: 194.4 | AH19: 282494087 | AK19: 37601 | AL19: 13.3 | AM19: 3674943 | AN19: 15057 | AO19: 4.1 | AR19: 232757930 | AS19: 70168831 | AT19: 0.301 | AU19: 328239523 | AV19: 79.05 | AW19: 330014476 | AX19: 1856446 | AY19: 112.5 | AZ19: 519512095 | BA19: 4.9 | BB19: 333266937 | BC19: 1045210 | BD19: 318.9 | BE19: 313.6 | BF19: 17571402 | BG19: 1220306 | BH19: 0.0694 | BI19: 196653543 | BJ19: 249750 | BK19: 127 | BL19: 167373333 | BM19: 12553 | BN19: 7.5 | BO19: 378139726 | BP19: 138021 | BQ19: 36.5 | BR19: 398716666 | BS19: 215307 | BT19: 54 | BU19: 192519457 | BV19: 212734 | BW19: 110.5 | BY19: 19004925 | BZ19: 54208780 | CA19: 31282896 | CB19: 45388153 | CC19: 42810359 | CD19: 41087357 | CE19: 42577475 | CF19: 54737648 | CG19: 218123424 | CH19: 41288572 | CI19: 19112979 | CJ19: 2786431 | CK19: 624863 | CL19: 20018544 | CM19: 29142780 | CN19: 125736353 | CO19: 105833 | CP19: 75149 | CQ19: 38445 | CR19: 83185 | CS19: 97644 | CT19: 113664 | CU19: 106473 | CV19: 104420 | CW19: 113370 | CX19: 0.1478 | CY19: 0.1805 | CZ19: 0.2962 | DA19: 0.2611 | DB19: 0.1143
A21: Averages
A22: Location | B22: Total Population | D22: % Male | E22: % Female | F22: Male | G22: Female | I22: Demographics by Age | J22: Age 0-4 | K22: Age 5-17 | L22: Age 18-24 | M22: Age 25-34 | N22: Age 35-44 | O22: Age 45-54 | P22: Age 55-64 | Q22: Age 65+
A23: Burke | B23: =AVERAGE(B5:C5) -> 82463.5 | D23: =(F23/B23)*100 -> 47.861175 | E23: =(G23/B23)*100 -> 52.138825 | F23: =AVERAGE(F5:G5) -> 39468 | G23: =AVERAGE(H5:I5) -> 42995.5 | J23: 1484 | K23: 4607 | L23: 2662 | M23: 2191 | N23: 3070 | O23: 2947 | P23: 3409 | Q23: 3967
A24: Columbia | B24: =AVERAGE(B6:C6) -> 557761.5 | D24: =(F24/B24)*100 -> 48.90836 | E24: =(G24/B24)*100 -> 51.09164 | F24: =AVERAGE(F6:G6) -> 272792 | G24: =AVERAGE(H6:I6) -> 284969.5 | J24: 9500 | K24: 29755 | L24: 12875 | M24: 21030 | N24: 22631 | O24: 19907 | P24: 18281 | Q24: 22942
A25: Emanuel | B25: =AVERAGE(B7:C7) -> 79718 | D25: =(F25/B25)*100 -> 49.966758 | E25: =(G25/B25)*100 -> 50.033242 | F25: =AVERAGE(F7:G7) -> 39832.5 | G25: =AVERAGE(H7:I7) -> 39885.5 | J25: 1585 | K25: 4132 | L25: 1917 | M25: 3249 | N25: 2881 | O25: 2571 | P25: 2907 | Q25: 3665
A26: Glascock | B26: =AVERAGE(B8:C8) -> 10332.5 | D26: =(F26/B26)*100 -> 49.073312 | E26: =(G26/B26)*100 -> 50.926688 | F26: =AVERAGE(F8:G8) -> 5070.5 | G26: =AVERAGE(H8:I8) -> 5262 | J26: 141 | K26: 481 | L26: 294 | M26: 262 | N26: 392 | O26: 424 | P26: 416 | Q26: 493
A27: Jefferson | B27: =AVERAGE(B9:C9) -> 53835.5 | D27: =(F27/B27)*100 -> 48.57111 | E27: =(G27/B27)*100 -> 51.42889 | F27: =AVERAGE(F9:G9) -> 26148.5 | G27: =AVERAGE(H9:I9) -> 27687 | J27: 921 | K27: 2709 | L27: 1411 | M27: 1778 | N27: 1987 | O27: 1786 | P27: 2123 | Q27: 2876
A28: Jenkins | B28: =AVERAGE(B10:C10) -> 30382 | D28: =(F28/B28)*100 -> 52.837206 | E28: =(G28/B28)*100 -> 47.162794 | F28: =AVERAGE(F10:G10) -> 16053 | G28: =AVERAGE(H10:I10) -> 14329 | J28: 266 | K28: 1357 | L28: 474 | M28: 910 | N28: 1379 | O28: 915 | P28: 1552 | Q28: 1851
A29: Lincoln | B29: =AVERAGE(B11:C11) -> 27531 | D29: =(F29/B29)*100 -> 48.563438 | E29: =(G29/B29)*100 -> 51.436562 | F29: =AVERAGE(F11:G11) -> 13370 | G29: =AVERAGE(H11:I11) -> 14161 | J29: 315 | K29: 1176 | L29: 540 | M29: 654 | N29: 953 | O29: 910 | P29: 1265 | Q29: 1913
A30: McDuffie | B30: =AVERAGE(B12:C12) -> 75432.5 | D30: =(F30/B30)*100 -> 47.185895 | E30: =(G30/B30)*100 -> 52.814105 | F30: =AVERAGE(F12:G12) -> 35593.5 | G30: =AVERAGE(H12:I12) -> 39839 | J30: 1358 | K30: 4044 | L30: 1608 | M30: 2770 | N30: 2500 | O30: 2534 | P30: 3008 | Q30: 3893
A31: Richmond | B31: =AVERAGE(B13:C13) -> 715015.5 | D31: =(F31/B31)*100 -> 48.462376 | E31: =(G31/B31)*100 -> 51.537624 | F31: =AVERAGE(F13:G13) -> 346513.5 | G31: =AVERAGE(H13:I13) -> 368502 | J31: 13503 | K31: 33728 | L31: 23345 | M31: 32995 | N31: 24866 | O31: 22088 | P31: 25637 | Q31: 29991
A32: Screven | B32: =AVERAGE(B14:C14) -> 49099 | D32: =(F32/B32)*100 -> 49.139494 | E32: =(G32/B32)*100 -> 50.860506 | F32: =AVERAGE(F14:G14) -> 24127 | G32: =AVERAGE(H14:I14) -> 24972 | J32: 763 | K32: 2123 | L32: 890 | M32: 1766 | N32: 1845 | O32: 1687 | P32: 2168 | Q32: 2784
A33: Taliaferro | B33: =AVERAGE(B15:C15) -> 5554.5 | D33: =(F33/B33)*100 -> 49.329373 | E33: =(G33/B33)*100 -> 50.670627 | F33: =AVERAGE(F15:G15) -> 2740 | G33: =AVERAGE(H15:I15) -> 2814.5 | J33: 67 | K33: 172 | L33: 96 | M33: 243 | N33: 206 | O33: 208 | P33: 186 | Q33: 457
A34: Warren | B34: =AVERAGE(B16:C16) -> 18217.5 | D34: =(F34/B34)*100 -> 47.190888 | E34: =(G34/B34)*100 -> 52.809112 | F34: =AVERAGE(F16:G16) -> 8597 | G34: =AVERAGE(H16:I16) -> 9620.5 | J34: 277 | K34: 780 | L34: 448 | M34: 502 | N34: 579 | O34: 619 | P34: 814 | Q34: 1178
... A36: Georgia (State) | B36: =AVERAGE(B18:C18) -> 37655454 | D36: =(F36/B36)*100 -> 48.727722 | E36: =(G36/B36)*100 -> 51.272278 | F36: =AVERAGE(F18:G18) -> 18348645 | G36: =AVERAGE(H18:I18) -> 19306810 | J36: 635299 | K36: 1877246 | L36: 1051160 | M36: 1475136 | N36: 1420198 | O36: 1401400 | P36: 1321441 | Q36: 1540445
A37: United States (as a whole) | B37: 331097593 | D37: =(F37/B37)*100 -> 49.592719 | E37: =(G37/B37)*100 -> 50.407281 | F37: 164200298 | G37: 166897295 | J37: 19004925 | K37: 54208780 | L37: 31282896 | M37: 45388153 | N37: 42810359 | O37: 41087357 | P37: 42577475 | Q37: 54737648
A56: County Health Rankings | B56: Demographics | S56: Health Outcomes | AG56: Health Behaviors | BA56: Clincial Care | BP56: Social and Economic Factors | CL56: Physical Environment
A58: Location | B58: Population | C58: Number of non -Hispanic White | D58: % White | E58: Number of non-Hispanic Black | F58: % Black | G58: Asian | H58: % Asian | I58: American Indian / Alaska Native | J58: % American Indian/ Alaskan Native | K58: Native Hawaiian / Pacific Islander | L58: % Native Hawaiian/ Pacific Islander | M58: Hispanic | N58: % Hispanic | O58: % Living in Rural Areas | P58: % Under Age of 18 | Q58: % 65 and Older | R58: % Female | S58: Life Expectancy (Years) | T58: Average Number of Poor Physical Health Days | U58: Premature Deaths | V58: Prematue Age-Adjusted Mortality Rate | W58: # of Child Deaths (1-20 yrs old) | X58: Child Mortality Rate | Y58: # of Infant Deaths | Z58: Infant Mortality Rate (0-12 months) / 1,000 births | AA58: % of Poor or Fair Health Days | AB58: % of Frequent Mental Distress | AC58: % of Adults with Diabetes | AD58: # of HIV Cases | AE58: HIV Prevelance Rate | AF58: % of Low Birth weight | AG58: Average Number of Poor Mental Health Days | AH58: % of Adults Reporting Currently Smoking | AI58: % of Adults with Obesity | AJ58: # With Food Insecurity | AK58: % With Food Insecurity | AL58: # With Limited Access to Healthy Foods | AM58: % With Limited Access to Healthy Foods | AN58: % With Insuffient Sleeping | AO58: Food Environment Index | AP58: % of Physical Inactivity | AQ58: % With Access to Exercise Opportunities | AR58: % of Excessive Drinking | AS58: Number of Alcohol-Impaired Driving Deaths | AT58: Number of Driving Deaths | AU58: % of Driving Deaths with Alcohol Inlvolvment | AV58: # of Drug Overdose Deaths | AW58: Drug Overdose Mortality Rate | AX58: Number of Chlamydia Cases | AY58: Chlamydia Rate | AZ58: Teen Birth Rate | BA58: Number of Uninsured | BB58: % Uninsured | BC58: # of Uninsured Adult | BD58: % of Uninsured Adults | BE58: # of Uninsured Children | BF58: % of Uninsured Childen | BG58: Number of Primary Care Physicians | BH58: Primary Care Physicians Ratio | BI58: Number of Dentists | BJ58: Dentists Ratio | BK58: Number of Mental Health Providers | BL58: Mental Health Providers Ratio | BM58: Preventable Hospital Stays | BN58: % of Population with annual Mammography Screening | BO58: % of population with Flu Vaccinations | BP58: Number Completed High School | BQ58: % of High School Compleiton | BR58: Cohort Size | BS58: High School Graduation Rate | BT58: Number of Some College | BU58: % of Some College | BV58: Number of Unemployed | BW58: Labor Force | BX58: % of Unemployed | BY58: % of Children in Poverty | BZ58: 80th Percentile Income | CA58: 20th Percentile Income | CB58: Median Household Income | CC58: Required Hourly Living Wage | CD58: Income Inequality Ratio | CE58: # of Children in Single-Parent Households | CF58: # of Children in Households | CG58: % of Children in Single Parent Housholds | CH58: Number of Social Associations | CI58: Social Associations Rate | CJ58: Number of Injury Deaths | CK58: Injury Death Rate | CL58: Average Daily PM2.5 | CM58: Presence of Water Violation | CN58: % of Severe Housing Problems | CO58: # of Homeowners | CP58: % of Homeowners | CQ58: # of Households with Severe Cost Burden | CR58: % of Househould with Severe Cost Burden | CS58: % of Households with Broadband Access | CT58: % of Long Commute who Drive Alone
